Workbook
Name __brm2: #REF!
Name _brm2: #REF!
Name A: #REF!
Name aaaa: #REF!
Name aaaa: #REF!
Name aaaa: #REF!
Name aaaa: #REF!
Name aaaa: #REF!
Name aaaa: #REF!
Name aaaa: #REF!
Name aaaa: #REF!
Name aaaa: #REF!
Name aaaa: #REF!
Name aaaa: #REF!
Name aaaa: #REF!
Name aaaa: #REF!
Name aaaa: #REF!
Name aaaa: #REF!
Name aaaa: #REF!
Name aaaa: #REF!
Name aaaa: #REF!
Name aaaa: #REF!
Name aaaa: #REF!
Name aaaa: #REF!
Name aaaa: #REF!
Name aaaa: #REF!
Name aaaa: #REF!
Name aaaa: #REF!
Name aaaa: #REF!
Name aaaa: #REF!
Name aaaa: #REF!
Name aaaa: #REF!
Name aaaa: #REF!
Name aaaa: #REF!
Name aaaa: #REF!
Name aaaa: #REF!
Name aaaa: #REF!
Name aaaa: #REF!
Name aaaa: #REF!
Name aaaa: #REF!
Name aaaa: #REF!
Name aaaa: #REF!
Name aaaa: #REF!
Name aaaa: #REF!
Name aaaa: #REF!
Name aaaa: #REF!
Name aaaa: #REF!
Name aaaa: #REF!
Name aaaa: #REF!
Name aaaa: #REF!
Name aaaa: #REF!
Name aaaa: #REF!
Name aaaa: #REF!
Name aaaa: #REF!
Name aaaa: #REF!
Name aaaaa: #REF!
Name aaaaa: #REF!
Name aaaaa: #REF!
Name aaaaa: #REF!
Name aaaaa: #REF!

Sheet KO
C11: Koptāme/Summary
C13: Būves nosaukums/Building: Daudzīvokļu ēka / Residental building C2-10
C14: Objekta nosaukums/Object: Dzīvojamās ēkas C2-10 jaunbūve/ Residential building C2-10
C15: Objekta adrese/Object adress: Andrejostas iela 35, Rīga, LV-1045
A21: Nr.p.k./No | B21: Tāmes Nr./No | C21: Objekta nosaukums/Description | D21: Objekta izmaksas euro/Total euro
A23: 1 | B23: 2 | C23: 3 | D23: =C23+1 -> 4
A24: 1 | B24: 0 | C24: Sagatavošanās un būvlaukuma uzturēšanas darbi/Site preparation and maintenance, demolishing | D24: =KS!D21 -> 0
A25: 2 | B25: 1 | C25: Būvdarbi/General construction work (structure and finishings) | D25: =KS!D45 -> 0
A26: 3 | B26: 2 | C26: Santehniskie darbi/Internal engineering systems (HVAC, WSS) | D26: =KS!D60 -> 0
A27: 4 | B27: 3 | C27: Elektromontāžas un vājstrāvu montāžas darbi/Electricity and low current | D27: =KS!D73 -> 0
A28: 5 | C28: Ēkas būvniecības izmaksas/Building construction costs | D28: =D25+D26+D27 -> 0
A29: 6 | B29: 4 | C29: Ārējie inženiertīkli/Territory networks | D29: =KS!D87 -> 0
A30: 7 | B30: 5 | C30: Labiekārtošana un piebraucamie ceļi/Territory, landscaping and roads | D30: =KS!D100 -> 0
A31: 8 | C31: Objekta izmaksas/Total | D31: =D24+D28+D29+D30 -> 0
A32: 9 | C32: Virsizdevumi/Overhead ( %) | D32: =ROUND(D31*8%,2) -> 0
A33: 10 | C33: t. sk. darba aizsardzība ( %) | D33: =ROUND(D32*0.05,2) -> 0
A34: 11 | C34: Peļņa/Profit ( %) | D34: =ROUND(D31*5%,2) -> 0
A35: 12 | C35: Pavisam kopā/Total | D35: =D31+D32+D34 -> 0
C37: Pievienotās vērtības nodoklis/PVN/Value Added Tax/VAT (21,00 %) | D37: =D35*0.21 -> 0

Sheet KS
C2: Kopsavilkuma aprēķins/Summary
C4: Būves nosaukums/Building: Daudzīvokļu ēka / Residental building C2-10
C5: Objekta nosaukums/Object: Dzīvojamās ēkas C2-10 jaunbūve/ Residential building C2-10
C6: Objekta adrese/Object adress: Andrejostas iela 35, Rīga, LV-1045
C9: Par kopējo summu, (euro)/For the total amount, (euro) | D9: =D106 -> 0
C10: Kopējā darbietilpība (c/h)/Total labor volume (w/h) | D10: =H102 -> 0
A15: N.p.k. | B15: Tāmes Nr./Estimate No | C15: Būvdarbu veids vai konstruktīvā elementa nosaukums/Description | D15: Tāmes izmaksas /Total cost | E15: Tai skaitā/Including | H15: Darbietilpība (c/h)/Labor volume (w/h)
E16: darba alga/ salary | F16: būvizstrādājumi/ materials | G16: mehānismi/ mechanisms
A17: 1 | B17: 2 | C17: 3 | D17: =C17+1 -> 4 | E17: =D17+1 -> 5 | F17: =E17+1 -> 6 | G17: =F17+1 -> 7 | H17: =G17+1 -> 8
A19: 1 | B19: 0 | C19: Sagatavošanās un būvlaukuma uzturēšanas darbi/Site preparation and maintenance, demolishing
A20: =A19+1 -> 2 | B20: 0-1 | C20: Būvlaukuma sagatavošanas darbi, pagaidu būves, uzturēšanas darbi/Site preparation and maintenance | D20: =SUM(E20:G20) -> 0 | E20: ='0-1'!M96 -> 0 | F20: ='0-1'!N96 -> 0 | G20: ='0-1'!O96 -> 0 | H20: ='0-1'!L96 -> 0
A21: =A20+1 -> 3 | B21: 0 | C21: Sagatavošanās un būvlaukuma uzturēšanas darbi/Site preparation and maintenance, demolishing | D21: =SUM(D20:D20) -> 0 | E21: =SUM(E20:E20) -> 0 | F21: =SUM(F20:F20) -> 0 | G21: =SUM(G20:G20) -> 0 | H21: =SUM(H20:H20) -> 0
A23: =A21+1 -> 4 | B23: 1 | C23: Būvdarbi/General construction work (structure and finishings)
A24: =A23+1 -> 5 | B24: 1-0 | C24: Zemes darbi/Earthworks | D24: =SUM(E24:G24) -> 0 | E24: ='1-0Z'!M19 -> 0 | F24: ='1-0Z'!N19 -> 0 | G24: ='1-0Z'!O19 -> 0 | H24: ='1-0Z'!L19 -> 0
A25: =A24+1 -> 6 | B25: 1-2 | C25: Pamatu plātne, pamati, režģoģi / Baseplate, foundations | D25: =SUM(E25:G25) -> 0 | E25: ='1-2Pp'!M50 -> 0 | F25: ='1-2Pp'!N50 -> 0 | G25: ='1-2Pp'!O50 -> 0 | H25: ='1-2Pp'!L50 -> 0
A26: =A25+1 -> 7 | B26: 1-3 | C26: Nesošās sienas un kolonnas/ Load-bearing walls, columns | D26: =SUM(E26:G26) -> 0 | E26: ='1-3S'!M85 -> 0 | F26: ='1-3S'!N85 -> 0 | G26: ='1-3S'!O85 -> 0 | H26: ='1-3S'!L85 -> 0
A27: =A26+1 -> 8 | B27: 1-4 | C27: Tērauda konstrukcijas /Steel structures | D27: =SUM(E27:G27) -> 0 | E27: ='1-4T'!M67 -> 0 | F27: ='1-4T'!N67 -> 0 | G27: ='1-4T'!O67 -> 0 | H27: ='1-4T'!L67 -> 0
A28: =A27+1 -> 9 | B28: 1-5 | C28: Pārsegumu, siju montāža / Slabs, beams | D28: =SUM(E28:G28) -> 0 | E28: ='1-5P'!M379 -> 0 | F28: ='1-5P'!N379 -> 0 | G28: ='1-5P'!O379 -> 0 | H28: ='1-5P'!L379 -> 0
A29: =A28+1 -> 10 | B29: 1-6 | C29: Kāpnes, margas / Staircases, railings | D29: =SUM(E29:G29) -> 0 | E29: ='1-6K'!M45 -> 0 | F29: ='1-6K'!N45 -> 0 | G29: ='1-6K'!O45 -> 0 | H29: ='1-6K'!L45 -> 0
A30: =A29+1 -> 11 | B30: 1-7 | C30: Jumta un jumta elementu montāža / Roof and roof elements | D30: =SUM(E30:G30) -> 0 | E30: ='1-7J'!M183 -> 0 | F30: ='1-7J'!N183 -> 0 | G30: ='1-7J'!O183 -> 0 | H30: ='1-7J'!L183 -> 0
A31: =A30+1 -> 12 | B31: 1-8 | C31: Fasādes konstrukcijas un apdare / Facade finishing | D31: =SUM(E31:G31) -> 0 | E31: ='1-8F'!M121 -> 0 | F31: ='1-8F'!N121 -> 0 | G31: ='1-8F'!O121 -> 0 | H31: ='1-8F'!L121 -> 0
A32: =A31+1 -> 13 | B32: 1-9 | C32: Fasādes stiklojums, logi / Facade windows | D32: =SUM(E32:G32) -> 0 | E32: ='1-9L'!M85 -> 0 | F32: ='1-9L'!N85 -> 0 | G32: ='1-9L'!O85 -> 0 | H32: ='1-9L'!L85 -> 0
A33: =A32+1 -> 14 | B33: 1-10 | C33: Grīdu pamatnes / Floor constructions | D33: =SUM(E33:G33) -> 0 | E33: ='1-10Gp'!M181 -> 0 | F33: ='1-10Gp'!N181 -> 0 | G33: ='1-10Gp'!O181 -> 0 | H33: ='1-10Gp'!L181 -> 0
A34: =A33+1 -> 15 | B34: 1-11 | C34: Sienu konstrukcijas, stikla starpsienas / Internal walls, glass walls | D34: =SUM(E34:G34) -> 0 | E34: ='1-11S'!M74 -> 0 | F34: ='1-11S'!N74 -> 0 | G34: ='1-11S'!O74 -> 0 | H34: ='1-11S'!L74 -> 0
A35: =A34+1 -> 16 | B35: 1-12-1 | C35: Grīdu apdares darbi koptelpās / Floor finishing common areas | D35: =SUM(E35:G35) -> 0 | E35: ='1-12-1G'!M26 -> 0 | F35: ='1-12-1G'!N26 -> 0 | G35: ='1-12-1G'!O26 -> 0 | H35: ='1-12-1G'!L26 -> 0
A36: =A35+1 -> 17 | B36: 1-12-2 | C36: Grīdu apdares darbi dzīvokļos/ Floor finishing apartments | D36: =SUM(E36:G36) -> 0 | E36: ='1-12-2G'!M46 -> 0 | F36: ='1-12-2G'!N46 -> 0 | G36: ='1-12-2G'!O46 -> 0 | H36: ='1-12-2G'!L46 -> 0
A37: =A36+1 -> 18 | B37: 1-13-1 | C37: Griestu konstrukcijas / Ceiling constructions | D37: =SUM(E37:G37) -> 0 | E37: ='1-13-1G'!M79 -> 0 | F37: ='1-13-1G'!N79 -> 0 | G37: ='1-13-1G'!O79 -> 0 | H37: ='1-13-1G'!L79 -> 0
A38: =A37+1 -> 19 | B38: 1-13-2 | C38: Griestu apdares darbi koptelpās/ Ceiling finishing common areas | D38: =SUM(E38:G38) -> 0 | E38: ='1-13-2G'!M22 -> 0 | F38: ='1-13-2G'!N22 -> 0 | G38: ='1-13-2G'!O22 -> 0 | H38: ='1-13-2G'!L22 -> 0
A39: =A38+1 -> 20 | B39: 1-13-3 | C39: Griestu apdares darbi dzīvokļos/ Ceiling finishing apartments | D39: =SUM(E39:G39) -> 0 | E39: ='1-13-3G'!M38 -> 0 | F39: ='1-13-3G'!N38 -> 0 | G39: ='1-13-3G'!O38 -> 0 | H39: ='1-13-3G'!L38 -> 0
A40: =A39+1 -> 21 | B40: 1-14-1 | C40: Sienu apdares darbi koptelpās/ Wall finishing common areas | D40: =SUM(E40:G40) -> 0 | E40: ='1-14-1S'!M21 -> 0 | F40: ='1-14-1S'!N21 -> 0 | G40: ='1-14-1S'!O21 -> 0 | H40: ='1-14-1S'!L21 -> 0
A41: =A40+1 -> 22 | B41: 1-14-2 | C41: Sienu apdares darbi dzīvokļos / Wall finishing apartments | D41: =SUM(E41:G41) -> 0 | E41: ='1-14-2S'!M45 -> 0 | F41: ='1-14-2S'!N45 -> 0 | G41: ='1-14-2S'!O45 -> 0 | H41: ='1-14-2S'!L45 -> 0
A42: =A41+1 -> 23 | B42: 1-15 | C42: Durvis, vārti, lūkas / Doors, gates, hatches | D42: =SUM(E42:G42) -> 0 | E42: ='1-15D'!M73 -> 0 | F42: ='1-15D'!N73 -> 0 | G42: ='1-15D'!O73 -> 0 | H42: ='1-15D'!L73 -> 0
A43: =A42+1 -> 24 | B43: 1-16 | C43: Dažādi darbi, lūkas / Different jobs, details | D43: =SUM(E43:G43) -> 0 | E43: ='1-16'!M22 -> 0 | F43: ='1-16'!N22 -> 0 | G43: ='1-16'!O22 -> 0 | H43: ='1-16'!L22 -> 0
A44: =A43+1 -> 25 | B44: 1-17 | C44: Lifti, eskalatori / Elevators, escalators | D44: =SUM(E44:G44) -> 0 | E44: ='1-17'!M17 -> 0 | F44: ='1-17'!N17 -> 0 | G44: ='1-17'!O17 -> 0 | H44: ='1-17'!L17 -> 0
A45: =A44+1 -> 26 | B45: 1 | C45: Būvdarbi/General construction work (structure and finishings) | D45: =SUM(D24:D44) -> 0 | E45: =SUM(E24:E44) -> 0 | F45: =SUM(F24:F44) -> 0 | G45: =SUM(G24:G44) -> 0 | H45: =SUM(H24:H44) -> 0
A47: =A45+1 -> 27 | B47: 2 | C47: Santehniskie darbi/Internal engineering systems (HVAC, WSS)
A48: =A47+1 -> 28 | B48: 2-1 | C48: Siltummehānika / Heat engineering | D48: =SUM(E48:G48) -> 0 | E48: ='2-1'!M197 -> 0 | F48: ='2-1'!N197 -> 0 | G48: ='2-1'!O197 -> 0 | H48: ='2-1'!L197 -> 0
A49: =A48+1 -> 29 | B49: 2-2 | C49: Apkure/Heating | D49: =SUM(E49:G49) -> 0 | E49: ='2-2'!M228 -> 0 | F49: ='2-2'!N228 -> 0 | G49: ='2-2'!O228 -> 0 | H49: ='2-2'!L228 -> 0
A50: =A49+1 -> 30 | B50: 2-3 | C50: Ventilācija/Ventilation | D50: =SUM(E50:G50) -> 0 | E50: ='2-3'!M400 -> 0 | F50: ='2-3'!N400 -> 0 | G50: ='2-3'!O400 -> 0 | H50: ='2-3'!L400 -> 0
A51: =A50+1 -> 31 | B51: 2-4 | C51: Klimata kontroles sistēma / Climate control systems | D51: =SUM(E51:G51) -> 0 | E51: ='2-4'!M153 -> 0 | F51: ='2-4'!N153 -> 0 | G51: ='2-4'!O153 -> 0 | H51: ='2-4'!L153 -> 0
...

Sheet A General requirements 
A1: Local estimate Nr. A
A2: General requirements
A4: =[1]KS!C4 -> Būves nosaukums/Building: C2-9
A5: =[1]KS!C5 -> Objekta nosaukums/Object: TEC ēkas pārbūve par atpūtas centru C2-9/TEC building reconstruction into a recreation center C2-9
A6: =[1]KS!C6 -> Objekta adrese/Object adress: Andrejostas iela 21, Rīga, LV-1045
A11: No. | B11: Name of construction work | C11: Unit | D11: Quantity | E11: Unit costs (EUR) | K11: Total costs (EUR)
E12: time rate (c/h) | F12: work rate (euro/h) | G12: Salary | H12: Materials | I12: Mechanisms | J12: Sum | K12: labor (c/h) | L12: Salary | M12: Materials | N12: Mechanisms | O12: Sum
B13: Page No. 1
B14: GENERAL REQUIREMENTS
B15: GENERAL | G15: =E15*F15 -> 0 | J15: =ROUND(SUM(G15:I15),2) -> 0 | K15: =ROUND(D15*E15,2) -> 0 | L15: =ROUND(D15*G15,2) -> 0 | M15: =ROUND(D15*H15,2) -> 0 | N15: =ROUND(D15*I15,2) -> 0 | O15: =ROUND(SUM(L15:N15),2) -> 0
A16: A | B16: Note 1: These General Requirements are applicable to the whole of the Works. Each Clause, Sub-Clause or Item is to be priced individually and the Tenderer shall not enter any lump sum(s) covering more than one, or all Clauses, Sub-Clauses or Items. | C16: item | D16: 1 | G16: =E16*F16 -> 0 | J16: =ROUND(SUM(G16:I16),2) -> 0 | K16: =ROUND(D16*E16,2) -> 0 | L16: =ROUND(D16*G16,2) -> 0 | M16: =ROUND(D16*H16,2) -> 0 | N16: =ROUND(D16*I16,2) -> 0 | O16: =ROUND(SUM(L16:N16),2) -> 0
A17: B | B17: Note 2: Where any Clause, Sub-Clause or Item has not been priced, has been ticked or has been dashed, it shall be deemed that the value of any such Clause, Sub-Clause or Item has been included elsewhere within the Contract Price. | C17: item | D17: 1 | G17: =E17*F17 -> 0 | J17: =ROUND(SUM(G17:I17),2) -> 0 | K17: =ROUND(D17*E17,2) -> 0 | L17: =ROUND(D17*G17,2) -> 0 | M17: =ROUND(D17*H17,2) -> 0 | N17: =ROUND(D17*I17,2) -> 0 | O17: =ROUND(SUM(L17:N17),2) -> 0
A18: C | B18: Note 3: The quantities inserted against items are estimated quantities for the Works for the purpose of Tender evaluation and not to be taken as actual or correct. Any errors in quantities is the Contractor’s risk. | C18: item | D18: 1 | G18: =E18*F18 -> 0 | J18: =ROUND(SUM(G18:I18),2) -> 0 | K18: =ROUND(D18*E18,2) -> 0 | L18: =ROUND(D18*G18,2) -> 0 | M18: =ROUND(D18*H18,2) -> 0 | N18: =ROUND(D18*I18,2) -> 0 | O18: =ROUND(SUM(L18:N18),2) -> 0
A19: D | B19: Note 4: The Lump sum Contract Price is deemed to cover the whole of the works as per Employer's Requirements, Drawings, Specifications, Basis of Design documents, including Schedule of Project Requirements, and whether or not included in the Pricing Schedule . | C19: item | D19: 1 | G19: =E19*F19 -> 0 | J19: =ROUND(SUM(G19:I19),2) -> 0 | K19: =ROUND(D19*E19,2) -> 0 | L19: =ROUND(D19*G19,2) -> 0 | M19: =ROUND(D19*H19,2) -> 0 | N19: =ROUND(D19*I19,2) -> 0 | O19: =ROUND(SUM(L19:N19),2) -> 0
A20: E | B20: Note 5: The unit rates inserted in the Pricing Schedule will be used to value any variations to the Works, whether omissions or additions. | C20: item | D20: 1 | G20: =E20*F20 -> 0 | J20: =ROUND(SUM(G20:I20),2) -> 0 | K20: =ROUND(D20*E20,2) -> 0 | L20: =ROUND(D20*G20,2) -> 0 | M20: =ROUND(D20*H20,2) -> 0 | N20: =ROUND(D20*I20,2) -> 0 | O20: =ROUND(SUM(L20:N20),2) -> 0
A21: F | B21: Note 6: The Tenderer should note that the General Requirements section of the Pricing Schedule shall be administered strictly in accordance with the Conditions of the Contract. Any obligations stated herein, which, in the opinion of the Engineer, are not performed, either in full or in part, shall be the subject of an instruction given by the Engineer in accordance with the Conditions of Contract. The valuation of such variation(s) shall be determined in accordance with the Conditions of Contract. | C21: item | D21: 1 | G21: =E21*F21 -> 0 | J21: =ROUND(SUM(G21:I21),2) -> 0 | K21: =ROUND(D21*E21,2) -> 0 | L21: =ROUND(D21*G21,2) -> 0 | M21: =ROUND(D21*H21,2) -> 0 | N21: =ROUND(D21*I21,2) -> 0 | O21: =ROUND(SUM(L21:N21),2) -> 0
A22: G | B22: Note 7: Fire protection of temporary site office, storage, etc. | C22: item | D22: 1 | G22: =E22*F22 -> 0 | J22: =ROUND(SUM(G22:I22),2) -> 0 | K22: =ROUND(D22*E22,2) -> 0 | L22: =ROUND(D22*G22,2) -> 0 | M22: =ROUND(D22*H22,2) -> 0 | N22: =ROUND(D22*I22,2) -> 0 | O22: =ROUND(SUM(L22:N22),2) -> 0
B24: Page 2 | G24: =E24*F24 -> 0 | J24: =ROUND(SUM(G24:I24),2) -> 0 | K24: =ROUND(D24*E24,2) -> 0 | L24: =ROUND(D24*G24,2) -> 0 | M24: =ROUND(D24*H24,2) -> 0 | N24: =ROUND(D24*I24,2) -> 0 | O24: =ROUND(SUM(L24:N24),2) -> 0
B25: Facilities for the Employer/Engineer Staff | G25: =E25*F25 -> 0 | J25: =ROUND(SUM(G25:I25),2) -> 0 | K25: =ROUND(D25*E25,2) -> 0 | L25: =ROUND(D25*G25,2) -> 0 | M25: =ROUND(D25*H25,2) -> 0 | N25: =ROUND(D25*I25,2) -> 0 | O25: =ROUND(SUM(L25:N25),2) -> 0
A26: A | B26: The Contractor shall provide vehicles for Employer/Engineer's use in accordance with Engineer's requirement including required insurance coverage and comply with all Authorities requirements. Any maintenance, parts and consumables including fuel shall be at the cost of the Contractor during construction and defects liability period. | C26: item | D26: N/A
A27: B | B27: The Contractor shall provide at all times for the duration of the Time for Completion and/or any agreed time extension all chainmen, staff and survey instruments as may be required by the Engineer for monitoring the proper construction and completion of the Works. | C27: item | D27: 1 | G27: =E27*F27 -> 0 | J27: =ROUND(SUM(G27:I27),2) -> 0 | K27: =ROUND(D27*E27,2) -> 0 | L27: =ROUND(D27*G27,2) -> 0 | M27: =ROUND(D27*H27,2) -> 0 | N27: =ROUND(D27*I27,2) -> 0 | O27: =ROUND(SUM(L27:N27),2) -> 0
A28: C | B28: The Contractor shall provide such labour, materials and transport as the Engineer's representative may require to assist him in carrying out tests and checks on materials and workmanship and setting out and measurement of works. | C28: item | D28: N/A
A29: D | B29: The Contractor shall include all the overtime charges for the Engineer's staff that are required to comply with Program of Works all in accordance with the Specification. | C29: item | D29: 1 | G29: =E29*F29 -> 0 | J29: =ROUND(SUM(G29:I29),2) -> 0 | K29: =ROUND(D29*E29,2) -> 0 | L29: =ROUND(D29*G29,2) -> 0 | M29: =ROUND(D29*H29,2) -> 0 | N29: =ROUND(D29*I29,2) -> 0 | O29: =ROUND(SUM(L29:N29),2) -> 0
B30: COMPLETION AND POST COMPLETION REQUIREMENTS | G30: =E30*F30 -> 0 | J30: =ROUND(SUM(G30:I30),2) -> 0 | K30: =ROUND(D30*E30,2) -> 0 | L30: =ROUND(D30*G30,2) -> 0 | M30: =ROUND(D30*H30,2) -> 0 | N30: =ROUND(D30*I30,2) -> 0 | O30: =ROUND(SUM(L30:N30),2) -> 0
B31: Operation and Maintenance Manuals | G31: =E31*F31 -> 0 | J31: =ROUND(SUM(G31:I31),2) -> 0 | K31: =ROUND(D31*E31,2) -> 0 | L31: =ROUND(D31*G31,2) -> 0 | M31: =ROUND(D31*H31,2) -> 0 | N31: =ROUND(D31*I31,2) -> 0 | O31: =ROUND(SUM(L31:N31),2) -> 0
A32: E | B32: The Contractor shall allow for the preparation and submission of Operation and Maintenance Manuals for each machine, equipment or any other item that requires future maintenance in the quantity and manner specified. | C32: item | D32: 1 | G32: =E32*F32 -> 0 | J32: =ROUND(SUM(G32:I32),2) -> 0 | K32: =ROUND(D32*E32,2) -> 0 | L32: =ROUND(D32*G32,2) -> 0 | M32: =ROUND(D32*H32,2) -> 0 | N32: =ROUND(D32*I32,2) -> 0 | O32: =ROUND(SUM(L32:N32),2) -> 0
B33: Hand Over Manuals | G33: =E33*F33 -> 0 | J33: =ROUND(SUM(G33:I33),2) -> 0 | K33: =ROUND(D33*E33,2) -> 0 | L33: =ROUND(D33*G33,2) -> 0 | M33: =ROUND(D33*H33,2) -> 0 | N33: =ROUND(D33*I33,2) -> 0 | O33: =ROUND(SUM(L33:N33),2) -> 0
A34: F | B34: The Contractor shall allow for the preparation and submission of Hand Over Manuals, in accordance with the Specification. | C34: item | D34: 1 | G34: =E34*F34 -> 0 | J34: =ROUND(SUM(G34:I34),2) -> 0 | K34: =ROUND(D34*E34,2) -> 0 | L34: =ROUND(D34*G34,2) -> 0 | M34: =ROUND(D34*H34,2) -> 0 | N34: =ROUND(D34*I34,2) -> 0 | O34: =ROUND(SUM(L34:N34),2) -> 0
B36: Page 3 | G36: =E36*F36 -> 0 | J36: =ROUND(SUM(G36:I36),2) -> 0 | K36: =ROUND(D36*E36,2) -> 0 | L36: =ROUND(D36*G36,2) -> 0 | M36: =ROUND(D36*H36,2) -> 0 | N36: =ROUND(D36*I36,2) -> 0 | O36: =ROUND(SUM(L36:N36),2) -> 0
B37: Warranties | G37: =E37*F37 -> 0 | J37: =ROUND(SUM(G37:I37),2) -> 0 | K37: =ROUND(D37*E37,2) -> 0 | L37: =ROUND(D37*G37,2) -> 0 | M37: =ROUND(D37*H37,2) -> 0 | N37: =ROUND(D37*I37,2) -> 0 | O37: =ROUND(SUM(L37:N37),2) -> 0
A38: A | B38: The Contractor shall allow for the preparation and submission of Warranties for each machine, equipment or any other item as specified within Contract Documents. | C38: item | D38: 1 | G38: =E38*F38 -> 0 | J38: =ROUND(SUM(G38:I38),2) -> 0 | K38: =ROUND(D38*E38,2) -> 0 | L38: =ROUND(D38*G38,2) -> 0 | M38: =ROUND(D38*H38,2) -> 0 | N38: =ROUND(D38*I38,2) -> 0 | O38: =ROUND(SUM(L38:N38),2) -> 0
B39: Assets register | G39: =E39*F39 -> 0 | J39: =ROUND(SUM(G39:I39),2) -> 0 | K39: =ROUND(D39*E39,2) -> 0 | L39: =ROUND(D39*G39,2) -> 0 | M39: =ROUND(D39*H39,2) -> 0 | N39: =ROUND(D39*I39,2) -> 0 | O39: =ROUND(SUM(L39:N39),2) -> 0
A40: B | B40: The Contractor shall allow for the preparation and submission of Assets register for the Completed Works as required under the Contract Documents. | C40: item | D40: 1 | G40: =E40*F40 -> 0 | J40: =ROUND(SUM(G40:I40),2) -> 0 | K40: =ROUND(D40*E40,2) -> 0 | L40: =ROUND(D40*G40,2) -> 0 | M40: =ROUND(D40*H40,2) -> 0 | N40: =ROUND(D40*I40,2) -> 0 | O40: =ROUND(SUM(L40:N40),2) -> 0
B41: As Built Drawings | G41: =E41*F41 -> 0 | J41: =ROUND(SUM(G41:I41),2) -> 0 | K41: =ROUND(D41*E41,2) -> 0 | L41: =ROUND(D41*G41,2) -> 0 | M41: =ROUND(D41*H41,2) -> 0 | N41: =ROUND(D41*I41,2) -> 0 | O41: =ROUND(SUM(L41:N41),2) -> 0
A42: C | B42: The Contractor shall allow for the preparation and submission of As Built Drawings at the times and in the quantity and manner specified or required by the Engineer. | C42: item | D42: 1 | G42: =E42*F42 -> 0 | J42: =ROUND(SUM(G42:I42),2) -> 0 | K42: =ROUND(D42*E42,2) -> 0 | L42: =ROUND(D42*G42,2) -> 0 | M42: =ROUND(D42*H42,2) -> 0 | N42: =ROUND(D42*I42,2) -> 0 | O42: =ROUND(SUM(L42:N42),2) -> 0
B43: Handover | G43: =E43*F43 -> 0 | J43: =ROUND(SUM(G43:I43),2) -> 0 | K43: =ROUND(D43*E43,2) -> 0 | L43: =ROUND(D43*G43,2) -> 0 | M43: =ROUND(D43*H43,2) -> 0 | N43: =ROUND(D43*I43,2) -> 0 | O43: =ROUND(SUM(L43:N43),2) -> 0
A44: D | B44: The Contractor shall allow for the perpetration and submission of any documents required for handover to the Authorities. | C44: item | D44: 1 | G44: =E44*F44 -> 0 | J44: =ROUND(SUM(G44:I44),2) -> 0 | K44: =ROUND(D44*E44,2) -> 0 | L44: =ROUND(D44*G44,2) -> 0 | M44: =ROUND(D44*H44,2) -> 0 | N44: =ROUND(D44*I44,2) -> 0 | O44: =ROUND(SUM(L44:N44),2) -> 0
B46: Page 4 | G46: =E46*F46 -> 0 | J46: =ROUND(SUM(G46:I46),2) -> 0 | K46: =ROUND(D46*E46,2) -> 0 | L46: =ROUND(D46*G46,2) -> 0 | M46: =ROUND(D46*H46,2) -> 0 | N46: =ROUND(D46*I46,2) -> 0 | O46: =ROUND(SUM(L46:N46),2) -> 0
B47: MANAGEMENT AND STAFF | G47: =E47*F47 -> 0 | J47: =ROUND(SUM(G47:I47),2) -> 0 | K47: =ROUND(D47*E47,2) -> 0 | L47: =ROUND(D47*G47,2) -> 0 | M47: =ROUND(D47*H47,2) -> 0 | N47: =ROUND(D47*I47,2) -> 0 | O47: =ROUND(SUM(L47:N47),2) -> 0
B48: The Contractor is to allow in his tender for all site administration and supervision costs including all necessary security arrangements (photographic security pass system, etc.), and the safety of the public and adjoining property and shall be liable for any claims arising from loss or damage suffered. | G48: =E48*F48 -> 0 | J48: =ROUND(SUM(G48:I48),2) -> 0 | K48: =ROUND(D48*E48,2) -> 0 | L48: =ROUND(D48*G48,2) -> 0 | M48: =ROUND(D48*H48,2) -> 0 | N48: =ROUND(D48*I48,2) -> 0 | O48: =ROUND(SUM(L48:N48),2) -> 0
...

Sheet B Day works 
A1: Local estimate Nr. B
A2: General requirements
A4: =[1]KS!C4 -> Būves nosaukums/Building: C2-9
A5: =[1]KS!C5 -> Objekta nosaukums/Object: TEC ēkas pārbūve par atpūtas centru C2-9/TEC building reconstruction into a recreation center C2-9
A6: =[1]KS!C6 -> Objekta adrese/Object adress: Andrejostas iela 21, Rīga, LV-1045
A11: No. | B11: Name of construction work | C11: Unit | D11: Quantity | E11: Rate (euro/h) | F11: TOTAL
B13: Page 1
B14: GENERALLY
A15: A | B15: The daywork schedule will be administered strictly in accordance with the General Conditions of Contract and the Particular Conditions of Contract.
A16: B | B16: The daywork schedule shall only be for labour, materials and plant outside of or in addition to the Scope of Works as required or reasonably implied by all Contract Documents and will be as approved by the Engineer.
A17: C | B17: The Contractor will be paid for daywork schedule items carried out during the course of the Contract at the rates tendered in this schedule of rates. Profit and overheads are not to be included in the actual rates but stated as a percentage to be added at the end of Labour, Materials & Plant Sections of this schedule of rates.
A18: D | B18: The time engaged in the authorized works will be certified and paid. In the event of labour or plant having to be brought to the site specially for an item of the dayworks schedule, then a reasonable allowance will be made for travelling time. The allowance for travelling time is to be agreed before the dayworks schedule item is executed.
A19: E | B19: Daywork schedule rates tendered by the Contractor will be carefully taken into account at the time Tenders are being considered.
A20: F | B20: This dayworks schedule may be used in relation to all or part of the works. Where an Authority standard BOQ format has been used for a specific part of the work (which may include a specific dayworks schedule), either dayworks schedule may be used, at the discretion of the Engineer.
B22: Page 2
B23: RATES OF LABOUR
A24: A | B24: The Daywork rates quoted for Labour are to be the NET amounts payable including for use and waste of hand tools, use of all ordinary non-mechanical plant, stagings, scaffolding, tarpaulins, use of electric, light and water for the Works etc., and all special inducements for working. Unless specifically authorised in writing by the Consultant, non-productive overtime or special rates for overtime will not be admissible. The cost of all insurance, supervisory staff, including engineers, foremen, instruments, etc. clerks, storemen etc. to be included in the percentage addition for profit and overheads.
A25: B | B25: The NET rates for labour shall be the rates for persons directly engaged in the Works on Site or in the Contractor's workshops located in Abu Dhabi.
B26: RATES FOR MATERIAL
A27: C | B27: Materials used as items of the daywork schedule shall be as specified for the Works. The rates shall include delivery to the Site. In the event any materials are required for use as items of the daywork schedule which are not included in the schedule, the current NET market price shall apply, plus a percentage for profit and overhead, as identified within this schedule, which shall include all costs for collecting from the site store yard, loading, transporting, unloading at the Site.
A28: D | B28: The NET unit cost of materials shall be the actual cost of materials purchased specifically for the Works, or materials used from the Contractor's stock charged at current market prices plus a reasonable allowance for delivery to the Site.
B29: RATES FOR PLANT
A30: E | B30: The definition of hire terms are as follows:
A31: F | B31: Hourly hire - any hour of any day less than eight hours.
A32: G | B32: Daily hire - an eight-hour day. In the event that more than eight hours in less than twenty-four hours are worked consecutively (excluding normal breaks, etc.), the excess hours will be paid for as a direct proportion of daily hire rates.
E33: 0
B34: Page 3
B35: RATES FOR PLANT (CONT'D)
A36: A | B36: Plant (other than small tools and workshop equipment and operatives) used in the daywork schedule shall be paid for at the rates included in the daywork schedule or at the rates approved in writing by the Engineer prior to the execution of the Works. The Contractor shall present to the Engineer his proposed rates for plant or equipment not included in the daywork schedule as soon as possible after he becomes aware of the requirement to utilize such plant.
A37: B | B37: Plant hire rates shall include for drivers, attendants and operators, cost of maintaining in proper working order, attendance in starting up and shutting down, refuelling and all fuel and power, oils, greases and cleaning materials, replacement and/or sharpening of tools and all other ancillary items including consumable spares.
A38: C | B38: Time engaged actually working only will be allowed. idle time in maintenance, standing time or travelling to the site will not be allowed.
E39: 0
B40: Page 4
B41: LABOUR ON SITE
A42: A | B42: Semi-skilled labourers | C42: hr | E42: Rate Only
A43: B | B43: Unskilled labourers | C43: hr | E43: Rate Only
A44: C | B44: Steel fixer / Bender | C44: hr | E44: Rate Only
A45: D | B45: Welder | C45: hr | E45: Rate Only
A46: E | B46: Banksman | C46: hr | E46: Rate Only
A47: F | B47: Carpenter | C47: hr | E47: Rate Only
...

Sheet 0-1
F1: Lokālā tāme Nr./Local estimate No | G1: 0-1
F2: Būvlaukuma sagatavošanas darbi, pagaidu būves, uzturēšanas darbi/Site preparation and maintenance
A4: =KS!C4 -> Būves nosaukums/Building: Daudzīvokļu ēka / Residental building C2-10
A5: =KS!C5 -> Objekta nosaukums/Object: Dzīvojamās ēkas C2-10 jaunbūve/ Residential building C2-10
A6: =KS!C6 -> Objekta adrese/Object adress: Andrejostas iela 35, Rīga, LV-1045 | M6: Tāmes izmaksas | P6: euro
P8: =P96 -> 0
F10: Vienības izmaksas/Unit rate | N10: Kopā uz visu apjomu/Total amount
A11: N.p.k./No | B11: Kods*/Code | C11: Būvdarbu nosaukums/Description of the construction work | D11: Mērvienība/ Unit | E11: Daudzums/ Quantity | F11: laika norma (c/h)/time rate (w/h) | G11: darba samaksas likme* (euro/h)/labour wage rate (euro/h)* | H11: darba alga/ salary | I11: būvizstrādājumi/ materials | J11: mehānismi/ mechanisms | K11: kopā/ total | L11: darbietilpība (c/h)/labor (w/h) | M11: darba alga/ salary | N11: būvizstrādājumi/ materials | O11: mehānismi/ mechanisms | P11: summa/ Total
A12: 1 | B12: 2 | C12: 3 | D12: 4 | E12: 5 | F12: =E12+1 -> 6 | G12: =F12+1 -> 7 | H12: =G12+1 -> 8 | I12: =H12+1 -> 9 | J12: =I12+1 -> 10 | K12: =J12+1 -> 11 | L12: =K12+1 -> 12 | M12: =L12+1 -> 13 | ... P12: =O12+1 -> 16
C14: Būvlaukuma sagatavošanas darbi un uzturēšana kopā ēkām C2-09 un C2-10/ Site preparation and maintenance for buildings C2-09 un C2-10
C15: Būvlaukuma aprīkojums, pagaidu būves saskaņā ar DOP daļas risinājumiem/ Construction site equipment, temporary structures in accordance with the solutions of the DOP part
A16: 1 | C16: Apsardzes telpas uzstādīšana. 6.0 x 2.5 m (izmēru nosaka uzņemējs)/ Security premises, cabin container type 2.5x6x2.35(m) | D16: gb | E16: 1
A17: =A16+1 -> 2 | C17: Caurlaides barjera/ Pass barrier | D17: gb | E17: 1
A18: =A17+1 -> 3 | C18: Elektro mehaniskas (hidrauliskas) teritorijas barjera / Electro-mechanical (hydraulic) area barrier | D18: gb | E18: 1
A19: =A18+1 -> 4 | C19: Mehaniskas teritorijas vārti / Mechanical area barrier | D19: gb | E19: 4
A20: =A19+1 -> 5 | C20: Elektro mehaniskas (hidrauliskas) teritorijas barjera (1.2m) / Electro-mechanical (hydraulic) area barrier | D20: gb | E20: 2
A21: =A20+1 -> 6 | C21: Ugunsdzēsības stenda uzstādīšana (stenda komplektācija saskaņā ar MK noteikumu "Ugunsdrošības noteikumi" prasībām) / Firefighting stand installation (stand assembly in accordance with the requirements of the Cabinet Regulation "Fire Safety Regulations") | D21: gb | E21: 3
A22: =A21+1 -> 7 | C22: Sauso biotualešu uzstādīšana. 1.5 x 1.5 m/ Installation of dry biotoilets. 1.5 x 1.5 m | D22: gb | E22: 15
A23: =A22+1 -> 8 | C23: Konteinera tipa sanitartehnisko telpu uzstādīšana 2.5 x 6.0 m Ieskaitot nomas, mobilizacijas, uzstādīšanas un demobilizācijas izmaksas / Installation of container-type sanitary facilities 2.5 x 6.0 m Including rental, mobilization, installation and demobilization costs | D23: gb | E23: 4
A24: =A23+1 -> 9 | C24: Sadzīves atkritumu konteinera uzstādīšana un apkalpošāna visā būvdarbu laikā / Installation and maintenance of a municipal waste container throughout the construction work | D24: kpl | E24: 2
A25: =A24+1 -> 10 | C25: Inženieru telpu uzstādīšana 2.5 x 6.0 m . Ieskaitot nomas, mobilizacijas, uzstādīšanas un demobilizācijas izmaksas ar ugunsdzēšamu aparātu/ Installation of engineering premises 2.5 x 6.0 m. Including rental, mobilization, installation and demobilization costs | D25: gb | E25: 8
A26: =A25+1 -> 11 | C26: Strādnieku telpu uzstādīšana 2.5 x 6.0 m Ieskaitot nomas, mobilizacijas, uzstādīšanas un demobilizācijas izmaksas ar ugunsdzēšamu aparātu/ Installation of workers' premises 2.5 x 6.0 m Including rental, mobilization, installation and demobilization costs | D26: gb | E26: 30
A27: =A26+1 -> 12 | C27: Konteinera tipa noliktavas telpu uzstādīšana 2.5 x 6.0 m Ieskaitot nomas, mobilizacijas, uzstādīšanas un demobilizācijas izmaksas. ar ugunsdzēšamu aparātu/ Installation of container-type warehouse premises 2.5 x 6.0 m Including rental, mobilization, installation and demobilization costs | D27: gb | E27: 11
A28: 13 | C28: Būvlaukuma pagaidu žogs. Pagaidu nožogojums "BEKAERT". Ieskaitot nomas, mobilizacijas, un demobilizācijas izmaksas. Temporary fence on the construction site. Temporary fencing "BEKAERT". Including rental, mobilization, installation and demobilization costs. | D28: m | E28: 946
A29: 14 | C29: Pagaidu ūdensvada pieslēguma izbūve, t.sk.:/ Construction of a temporary water supply connection, including: | D29: kpl | E29: 1
A30: 14.1 | C30: Noteikumu pagaidu pieslēguma izbūvei pieprasīšana / Requesting regulations for the construction of a temporary connection | D30: kpl | E30: 1
A31: 14.2 | C31: ūdensskaitītājs DN15/ water meter DN15 | D31: gb | E31: 1
A32: 14.3 | C32: cauruļvads DN25 ar uzsildīšanu/ DN25 pipeline with heating | D32: kpl | E32: 1
A33: 15 | C33: Pagaidu spices izbūvēšana un tamponēšana/ setting and dismantling of temporal spoke | D33: kpl | E33: 4
A34: =A33+1 -> 16 | C34: Pagaidu elektroapgādes pieslēguma izbūve, t.sk., skatīt ELT-sadaļu:/ Construction of temporary power supply connection, including: | D34: kpl | E34: 1
A35: 16.1 | C35: pagaidu sadales kaste 150 kW / 380 V / 50 Hz / 3 fāzes/ temporary distribution box 150 kW / 380 V / 50 Hz / 3 phases; | D35: gb | E35: 8
A36: 16.2 | C36: 2 kabeļi ar atbilstošu šķērsgriezumu, L vienam kabelim/ 2 cables with corresponding cross-section, L for one cable. | D36: kpl | E36: 1
A37: 17 | C37: Būvlaukuma Apgaismojums Lighting
A38: 17.1 | C38: Būvlaukums. Apgaismojuma masts ar LED prožektoru 50 W (100W) uz 9 m augsta staba un elektropieslēgumu (stabs) / Lighting mast with LED floodlight 50 W (100W) on 9 m high pole and electrical connection. Stabs/ mast | D38: gb | E38: 18
A39: 17.2 | C39: Būvlaukums. Apgaismojuma masts ar LED prožektoru 50 W (100W) uz 9 m augsta staba un elektropieslēgumu (stabs) / Lighting mast with LED floodlight 50 W (100W) on 9 m high pole and electrical connection. Prožektors/ floodlight | D39: gb | E39: 36
A40: 18 | C40: Būvnieku pilsētiņa. Apgaismojums
A41: 18.1 | C41: Būvnieku pilsetiņa. Apgaismojuma masts ar LED prožektoru 50 W (100W) uz 9 m augsta staba un elektropieslēgumu (stabs) / Lighting mast with LED floodlight 50 W (100W) on 9 m high pole and electrical connection. Stabs/ mast | D41: gb | E41: 9
A42: 18.2 | C42: Būvnieku pilsetiņa. Apgaismojuma masts ar LED prožektoru 50 W (100W) uz 9 m augsta staba un elektropieslēgumu (stabs) / Lighting mast with LED floodlight 50 W (100W) on 9 m high pole and electrical connection. Prožektors/ floodlight | D42: gb | E42: 18
A43: 19 | C43: Pagaidu EST pieslēguma izbūve / Construction of a temporary EST connection | D43: kpl | E43: 1
A44: =A43+1 -> 20 | C44: Būvlaukuma video monitorings/ Construction site video monitoring | D44: kpl | E44: 1
...

Sheet 1-0Z
F1: Lokālā tāme Nr./Local estimate No | G1: 1-0
F2: Zemes darbi/Earthworks
A4: =KS!C4 -> Būves nosaukums/Building: Daudzīvokļu ēka / Residental building C2-10
A5: =KS!C5 -> Objekta nosaukums/Object: Dzīvojamās ēkas C2-10 jaunbūve/ Residential building C2-10
A6: =KS!C6 -> Objekta adrese/Object adress: Andrejostas iela 35, Rīga, LV-1045 | M6: Tāmes izmaksas | O6: 0
P8: Tāme sastādīta/Date _____. gada ____. ____________
F10: Vienības izmaksas/Unit rate | N10: Kopā uz visu apjomu/Total amount
A11: N.p.k./No | B11: Kods*/Code | C11: Būvdarbu nosaukums/Description of the construction work | D11: Mērvienība/ Unit | E11: Daudzums/ Quantity | F11: laika norma (c/h)/time rate (w/h) | G11: darba samaksas likme* (euro/h)/labour wage rate (euro/h)* | H11: darba alga/ salary | I11: būvizstrādājumi/ materials | J11: mehānismi/ mechanisms | K11: kopā/ total | L11: darbietilpība (c/h)/labor (w/h) | M11: darba alga/ salary | N11: būvizstrādājumi/ materials | O11: mehānismi/ mechanisms | P11: summa/ Total
A12: 1 | B12: 2 | C12: 3 | D12: 4 | E12: 5 | F12: =E12+1 -> 6 | G12: =F12+1 -> 7 | H12: =G12+1 -> 8 | I12: =H12+1 -> 9 | J12: =I12+1 -> 10 | K12: =J12+1 -> 11 | L12: =K12+1 -> 12 | M12: =L12+1 -> 13 | ... P12: =O12+1 -> 16
C14: C2-10
A15: 1 | C15: Būvbedres grunts izstrāde zem ēkas C2-9/ Excavated soil under the building | D15: m3 | E15: 9647
A16: =A15+1 -> 2 | C16: Grunts iekraušana un izvešana būvlaukuma atbērtnē (apjoms norādīts sablīvētā veidā) /Loading and unloading of soil at the construction site (volume is indicated in compacted form) | D16: m3 | E16: 9647
A17: =A16+1 -> 3 | C17: Būvbedres aizbēršana ar pievesto smilti (apjoms norādīts sablīvētā veidā), zem ēkas/Backfilling of a construction pit with applied sand (volume is indicated in compacted form) under the building | D17: m3 | E17: 2992.5
C19: Izmaksas kopā, t. sk. darba devēja sociālais nodoklis (%) /Total costs, including employer's social tax (%) | L19: =SUM($L$13:L18) -> 0 | M19: =SUM($M$13:M18) -> 0 | N19: =SUM($N$13:N18) -> 0 | O19: =SUM($O$13:O18) -> 0 | P19: =SUM($P$13:P18) -> 0

Sheet 1-2Pp
F1: Lokālā tāme Nr./Local estimate No | G1: 1-2
F2: Pamatu plātne, pamati, režģoģi / Baseplate, foundations
A4: =KS!C4 -> Būves nosaukums/Building: Daudzīvokļu ēka / Residental building C2-10
A5: =KS!C5 -> Objekta nosaukums/Object: Dzīvojamās ēkas C2-10 jaunbūve/ Residential building C2-10
A6: =KS!C6 -> Objekta adrese/Object adress: Andrejostas iela 35, Rīga, LV-1045 | M6: Tāmes izmaksas | O6: 0
P8: Tāme sastādīta/Date _____. gada ____. ____________
F10: Vienības izmaksas/Unit rate | N10: Kopā uz visu apjomu/Total amount
A11: N.p.k./No | B11: Kods*/Code | C11: Būvdarbu nosaukums/Description of the construction work | D11: Mērvienība/ Unit | E11: Daudzums/ Quantity | F11: laika norma (c/h)/time rate (w/h) | G11: darba samaksas likme* (euro/h)/labour wage rate (euro/h)* | H11: darba alga/ salary | I11: būvizstrādājumi/ materials | J11: mehānismi/ mechanisms | K11: kopā/ total | L11: darbietilpība (c/h)/labor (w/h) | M11: darba alga/ salary | N11: būvizstrādājumi/ materials | O11: mehānismi/ mechanisms | P11: summa/ Total
A12: 1 | B12: 2 | C12: 3 | D12: 4 | E12: 5 | F12: =E12+1 -> 6 | G12: =F12+1 -> 7 | H12: =G12+1 -> 8 | I12: =H12+1 -> 9 | J12: =I12+1 -> 10 | K12: =J12+1 -> 11 | L12: =K12+1 -> 12 | M12: =L12+1 -> 13 | ... P12: =O12+1 -> 16
C14: Monolītā dzelzsbetona pamatu plātnes un režģoģi / Reinforced concrete foundation slabs and pile caps
A15: 1 | C15: Pamatnes betonēšana b=100 mm Betons C40/50 ar kristalizējošu piedevu SHOMBURG BETOCRETE-CP-360-WP, betons ar betona piegādi, sūknēšanu, vibrēšanu, līdzināšanu, mitrināšanu, plēves piesegšanu, tehnoloģisko un deformācijas šuvju izveidi, ieliekamo detaļu iebetonēšanu, ja nepieciešams/Reinforced concrete floor b=100 mm, Concrete C40/50 whith crystallizing additive SHOMBURG BETOCRETE-CP-360-WP, concrete with concrete delivery, pumping, vibrating, leveling, wetting, covering with film, creating technological and deformation joints, concreting of insert parts, if necessary | D15: m3 | E15: 128.54
A16: =A15+1 -> 2 | C16: Pamatnes betonēšana b=110 mm Betons C40/50 ar kristalizējošu piedevu SHOMBURG BETOCRETE-CP-360-WP, betons ar betona piegādi, sūknēšanu, vibrēšanu, līdzināšanu, mitrināšanu, plēves piesegšanu, tehnoloģisko un deformācijas šuvju izveidi, ieliekamo detaļu iebetonēšanu, ja nepieciešams/Reinforced concrete floor b=110 mm, Concrete C40/50 whith crystallizing additive SHOMBURG BETOCRETE-CP-360-WP, concrete with concrete delivery, pumping, vibrating, leveling, wetting, covering with film, creating technological and deformation joints, concreting of insert parts, if necessary | D16: m3 | E16: 13.67
A17: =A16+1 -> 3 | C17: Pamatnes betonēšana b=220 mm Betons C40/50 ar kristalizējošu piedevu SHOMBURG BETOCRETE-CP-360-WP, betons ar betona piegādi, sūknēšanu, vibrēšanu, līdzināšanu, mitrināšanu, plēves piesegšanu, tehnoloģisko un deformācijas šuvju izveidi, ieliekamo detaļu iebetonēšanu, ja nepieciešams/Reinforced concrete floor b=220 mm, Concrete C40/50 whith crystallizing additive SHOMBURG BETOCRETE-CP-360-WP, concrete with concrete delivery, pumping, vibrating, leveling, wetting, covering with film, creating technological and deformation joints, concreting of insert parts, if necessary | D17: m3 | E17: 4.09
A18: =A17+1 -> 4 | C18: Pamatnes betonēšana b=300 mm Betons C40/50 ar kristalizējošu piedevu SHOMBURG BETOCRETE-CP-360-WP, betons ar betona piegādi, sūknēšanu, vibrēšanu, līdzināšanu, mitrināšanu, plēves piesegšanu, tehnoloģisko un deformācijas šuvju izveidi, ieliekamo detaļu iebetonēšanu, ja nepieciešams/Reinforced concrete floor b=300 mm, Concrete C40/50 whith crystallizing additive SHOMBURG BETOCRETE-CP-360-WP, concrete with concrete delivery, pumping, vibrating, leveling, wetting, covering with film, creating technological and deformation joints, concreting of insert parts, if necessary | D18: m3 | E18: 952.31
A19: =A18+1 -> 5 | C19: Pamatnes betonēšana b=400 mm Betons C40/50 ar kristalizējošu piedevu SHOMBURG BETOCRETE-CP-360-WP, betons ar betona piegādi, sūknēšanu, vibrēšanu, līdzināšanu, mitrināšanu, plēves piesegšanu, tehnoloģisko un deformācijas šuvju izveidi, ieliekamo detaļu iebetonēšanu, ja nepieciešams/Reinforced concrete floor b=400 mm, Concrete C40/50 whith crystallizing additive SHOMBURG BETOCRETE-CP-360-WP, concrete with concrete delivery, pumping, vibrating, leveling, wetting, covering with film, creating technological and deformation joints, concreting of insert parts, if necessary | D19: m3 | E19: 2.51
A20: =A19+1 -> 6 | C20: Pamatnes betonēšana b=530 mm Betons C40/50 ar kristalizējošu piedevu SHOMBURG BETOCRETE-CP-360-WP, betons ar betona piegādi, sūknēšanu, vibrēšanu, līdzināšanu, mitrināšanu, plēves piesegšanu, tehnoloģisko un deformācijas šuvju izveidi, ieliekamo detaļu iebetonēšanu, ja nepieciešams/Reinforced concrete floor b=530 mm, Concrete C40/50 whith crystallizing additive SHOMBURG BETOCRETE-CP-360-WP, concrete with concrete delivery, pumping, vibrating, leveling, wetting, covering with film, creating technological and deformation joints, concreting of insert parts, if necessary | D20: m3 | E20: 17.79
A21: =A20+1 -> 7 | C21: Pamatnes malas 230x230mm betonēšana Betons C40/50 ar kristalizējošu piedevu SHOMBURG BETOCRETE-CP-360-WP, betons ar betona piegādi, sūknēšanu, vibrēšanu, līdzināšanu, mitrināšanu, plēves piesegšanu, tehnoloģisko un deformācijas šuvju izveidi, ieliekamo detaļu iebetonēšanu, ja nepieciešams/Reinforced concrete floor Slab_Edge_230x230mm, Concrete C40/50 whith crystallizing additive SHOMBURG BETOCRETE-CP-360-WP, concrete with concrete delivery, pumping, vibrating, leveling, wetting, covering with film, creating technological and deformation joints, concreting of insert parts, if necessary | D21: m3 | E21: 0.86
A22: =A21+1 -> 8 | C22: Pamatnes stiegrošana, t. sk palīgmateriāli (distanceri, sienamās stieples, konusi, uzgriežņi u.c.), stiegrojums B500B / Slab reinforcement and consumables (spacers, wall wires, cones, bolts etc.), reinforcement B500B | D22: t | E22: 134.37
A23: =A22+1 -> 9 | C23: Veidņu (apjoms precizējams veidņu izklājumā) , tsk. (palīgmateriāli (kokmateriāli, saplāksnis, stiprinājumi, caurlītes, konusi, aizbāžņi, eļļa, plēve) montāža, noma, demontāža režģogiem/ Formwork (volume to be specified in the formwork layout), incl. (auxiliary materials (timber, plywood, fasteners, tubes, cones, plugs, oil, film) assembly, rental, dismantling | D23: kpl | E23: 1
A24: =A23+1 -> 10 | B24: Cap_500mm | C24: Režģogu betonēšana Betons C40/50 ar kristalizējošu piedevu SHOMBURG BETOCRETE-CP-360-WP, betons ar betona piegādi, sūknēšanu, vibrēšanu, līdzināšanu, mitrināšanu, plēves piesegšanu, tehnoloģisko un deformācijas šuvju izveidi, ieliekamo detaļu iebetonēšanu, ja nepieciešams/ Pile cap , Concrete C40/50 whith crystallizing additive SHOMBURG BETOCRETE-CP-360-WP, concrete with concrete delivery, pumping, vibrating, leveling, wetting, covering with film, creating technological and deformation joints, concreting of insert parts, if necessary | D24: m3 | E24: 22.28
A25: =A24+1 -> 11 | B25: Cap_600mm | C25: Režģogu betonēšana Betons C40/50 ar kristalizējošu piedevu SHOMBURG BETOCRETE-CP-360-WP, betons ar betona piegādi, sūknēšanu, vibrēšanu, līdzināšanu, mitrināšanu, plēves piesegšanu, tehnoloģisko un deformācijas šuvju izveidi, ieliekamo detaļu iebetonēšanu, ja nepieciešams/ Pile cap , Concrete C40/50 whith crystallizing additive SHOMBURG BETOCRETE-CP-360-WP, concrete with concrete delivery, pumping, vibrating, leveling, wetting, covering with film, creating technological and deformation joints, concreting of insert parts, if necessary | D25: m3 | E25: 12.96
A26: 11.1 | B26: Cap_650mm | C26: Režģogu betonēšana Betons C40/50 ar kristalizējošu piedevu SHOMBURG BETOCRETE-CP-360-WP, betons ar betona piegādi, sūknēšanu, vibrēšanu, līdzināšanu, mitrināšanu, plēves piesegšanu, tehnoloģisko un deformācijas šuvju izveidi, ieliekamo detaļu iebetonēšanu, ja nepieciešams/ Pile cap , Concrete C40/50 whith crystallizing additive SHOMBURG BETOCRETE-CP-360-WP, concrete with concrete delivery, pumping, vibrating, leveling, wetting, covering with film, creating technological and deformation joints, concreting of insert parts, if necessary | D26: m3 | E26: 4.88
A27: =A25+1 -> 12 | B27: Cap_800mm | C27: Režģogu betonēšana Betons C40/50 ar kristalizējošu piedevu SHOMBURG BETOCRETE-CP-360-WP, betons ar betona piegādi, sūknēšanu, vibrēšanu, līdzināšanu, mitrināšanu, plēves piesegšanu, tehnoloģisko un deformācijas šuvju izveidi, ieliekamo detaļu iebetonēšanu, ja nepieciešams/ Pile cap , Concrete C40/50 whith crystallizing additive SHOMBURG BETOCRETE-CP-360-WP, concrete with concrete delivery, pumping, vibrating, leveling, wetting, covering with film, creating technological and deformation joints, concreting of insert parts, if necessary | D27: m3 | E27: 6.84
A28: =A27+1 -> 13 | B28: Cap_900mm | C28: Režģogu betonēšana Betons C40/50 ar kristalizējošu piedevu SHOMBURG BETOCRETE-CP-360-WP, betons ar betona piegādi, sūknēšanu, vibrēšanu, līdzināšanu, mitrināšanu, plēves piesegšanu, tehnoloģisko un deformācijas šuvju izveidi, ieliekamo detaļu iebetonēšanu, ja nepieciešams/ Pile cap , Concrete C40/50 whith crystallizing additive SHOMBURG BETOCRETE-CP-360-WP, concrete with concrete delivery, pumping, vibrating, leveling, wetting, covering with film, creating technological and deformation joints, concreting of insert parts, if necessary | D28: m3 | E28: 474.78
A29: =A28+1 -> 14 | B29: Cap_1100mm | C29: Režģogu betonēšana Betons C40/50 ar kristalizējošu piedevu SHOMBURG BETOCRETE-CP-360-WP, betons ar betona piegādi, sūknēšanu, vibrēšanu, līdzināšanu, mitrināšanu, plēves piesegšanu, tehnoloģisko un deformācijas šuvju izveidi, ieliekamo detaļu iebetonēšanu, ja nepieciešams/ Pile cap , Concrete C40/50 whith crystallizing additive SHOMBURG BETOCRETE-CP-360-WP, concrete with concrete delivery, pumping, vibrating, leveling, wetting, covering with film, creating technological and deformation joints, concreting of insert parts, if necessary | D29: m3 | E29: 417.42
A30: =A29+1 -> 15 | B30: Cap_1300mm | C30: Režģogu betonēšana Betons C40/50 ar kristalizējošu piedevu SHOMBURG BETOCRETE-CP-360-WP, betons ar betona piegādi, sūknēšanu, vibrēšanu, līdzināšanu, mitrināšanu, plēves piesegšanu, tehnoloģisko un deformācijas šuvju izveidi, ieliekamo detaļu iebetonēšanu, ja nepieciešams/ Pile cap , Concrete C40/50 whith crystallizing additive SHOMBURG BETOCRETE-CP-360-WP, concrete with concrete delivery, pumping, vibrating, leveling, wetting, covering with film, creating technological and deformation joints, concreting of insert parts, if necessary | D30: m3 | E30: 339.73
A31: =A30+1 -> 16 | B31: Cap_1400mm | C31: Režģogu betonēšana Betons C40/50 ar kristalizējošu piedevu SHOMBURG BETOCRETE-CP-360-WP, betons ar betona piegādi, sūknēšanu, vibrēšanu, līdzināšanu, mitrināšanu, plēves piesegšanu, tehnoloģisko un deformācijas šuvju izveidi, ieliekamo detaļu iebetonēšanu, ja nepieciešams/ Pile cap , Concrete C40/50 whith crystallizing additive SHOMBURG BETOCRETE-CP-360-WP, concrete with concrete delivery, pumping, vibrating, leveling, wetting, covering with film, creating technological and deformation joints, concreting of insert parts, if necessary | D31: m3 | E31: 74.52
A32: 16.1 | B32: R-6.1 | C32: Režģogu betonēšana Betons C40/50 ar kristalizējošu piedevu SHOMBURG BETOCRETE-CP-360-WP, betons ar betona piegādi, sūknēšanu, vibrēšanu, līdzināšanu, mitrināšanu, plēves piesegšanu, tehnoloģisko un deformācijas šuvju izveidi, ieliekamo detaļu iebetonēšanu, ja nepieciešams/ Pile cap , Concrete C40/50 whith crystallizing additive SHOMBURG BETOCRETE-CP-360-WP, concrete with concrete delivery, pumping, vibrating, leveling, wetting, covering with film, creating technological and deformation joints, concreting of insert parts, if necessary | D32: m3 | E32: 0.42
A33: 16.2 | B33: R-7.1 | C33: Režģogu betonēšana Betons C40/50 ar kristalizējošu piedevu SHOMBURG BETOCRETE-CP-360-WP, betons ar betona piegādi, sūknēšanu, vibrēšanu, līdzināšanu, mitrināšanu, plēves piesegšanu, tehnoloģisko un deformācijas šuvju izveidi, ieliekamo detaļu iebetonēšanu, ja nepieciešams/ Pile cap , Concrete C40/50 whith crystallizing additive SHOMBURG BETOCRETE-CP-360-WP, concrete with concrete delivery, pumping, vibrating, leveling, wetting, covering with film, creating technological and deformation joints, concreting of insert parts, if necessary | D33: m3 | E33: 1.06
A34: 16.3 | B34: R-8.1 | C34: Režģogu betonēšana Betons C40/50 ar kristalizējošu piedevu SHOMBURG BETOCRETE-CP-360-WP, betons ar betona piegādi, sūknēšanu, vibrēšanu, līdzināšanu, mitrināšanu, plēves piesegšanu, tehnoloģisko un deformācijas šuvju izveidi, ieliekamo detaļu iebetonēšanu, ja nepieciešams/ Pile cap , Concrete C40/50 whith crystallizing additive SHOMBURG BETOCRETE-CP-360-WP, concrete with concrete delivery, pumping, vibrating, leveling, wetting, covering with film, creating technological and deformation joints, concreting of insert parts, if necessary | D34: m3 | E34: 1.06
A35: 16.4 | B35: R-9.1 | C35: Režģogu betonēšana Betons C40/50 ar kristalizējošu piedevu SHOMBURG BETOCRETE-CP-360-WP, betons ar betona piegādi, sūknēšanu, vibrēšanu, līdzināšanu, mitrināšanu, plēves piesegšanu, tehnoloģisko un deformācijas šuvju izveidi, ieliekamo detaļu iebetonēšanu, ja nepieciešams/ Pile cap , Concrete C40/50 whith crystallizing additive SHOMBURG BETOCRETE-CP-360-WP, concrete with concrete delivery, pumping, vibrating, leveling, wetting, covering with film, creating technological and deformation joints, concreting of insert parts, if necessary | D35: m3 | E35: 4.72
A36: =A31+1 -> 17 | B36: R-3.1 | C36: Režģogu betonēšana Betons C40/50 ar kristalizējošu piedevu SHOMBURG BETOCRETE-CP-360-WP, betons ar betona piegādi, sūknēšanu, vibrēšanu, līdzināšanu, mitrināšanu, plēves piesegšanu, tehnoloģisko un deformācijas šuvju izveidi, ieliekamo detaļu iebetonēšanu, ja nepieciešams/ Pile cap , Concrete C40/50 whith crystallizing additive SHOMBURG BETOCRETE-CP-360-WP, concrete with concrete delivery, pumping, vibrating, leveling, wetting, covering with film, creating technological and deformation joints, concreting of insert parts, if necessary | D36: m3 | E36: 6.77
A37: =A36+1 -> 18 | B37: R-4.1 | C37: Režģogu betonēšana Betons C40/50 ar kristalizējošu piedevu SHOMBURG BETOCRETE-CP-360-WP, betons ar betona piegādi, sūknēšanu, vibrēšanu, līdzināšanu, mitrināšanu, plēves piesegšanu, tehnoloģisko un deformācijas šuvju izveidi, ieliekamo detaļu iebetonēšanu, ja nepieciešams/ Pile cap , Concrete C40/50 whith crystallizing additive SHOMBURG BETOCRETE-CP-360-WP, concrete with concrete delivery, pumping, vibrating, leveling, wetting, covering with film, creating technological and deformation joints, concreting of insert parts, if necessary | D37: m3 | E37: 21.81
A38: =A37+1 -> 19 | B38: R-6.1 | C38: Režģogu betonēšana Betons C40/50 ar kristalizējošu piedevu SHOMBURG BETOCRETE-CP-360-WP, betons ar betona piegādi, sūknēšanu, vibrēšanu, līdzināšanu, mitrināšanu, plēves piesegšanu, tehnoloģisko un deformācijas šuvju izveidi, ieliekamo detaļu iebetonēšanu, ja nepieciešams/ Pile cap , Concrete C40/50 whith crystallizing additive SHOMBURG BETOCRETE-CP-360-WP, concrete with concrete delivery, pumping, vibrating, leveling, wetting, covering with film, creating technological and deformation joints, concreting of insert parts, if necessary | D38: m3 | E38: 14.99
A39: =A38+1 -> 20 | B39: R-7.1 | C39: Režģogu betonēšana Betons C40/50 ar kristalizējošu piedevu SHOMBURG BETOCRETE-CP-360-WP, betons ar betona piegādi, sūknēšanu, vibrēšanu, līdzināšanu, mitrināšanu, plēves piesegšanu, tehnoloģisko un deformācijas šuvju izveidi, ieliekamo detaļu iebetonēšanu, ja nepieciešams/ Pile cap , Concrete C40/50 whith crystallizing additive SHOMBURG BETOCRETE-CP-360-WP, concrete with concrete delivery, pumping, vibrating, leveling, wetting, covering with film, creating technological and deformation joints, concreting of insert parts, if necessary | D39: m3 | E39: 84.19
A40: =A39+1 -> 21 | B40: R-8.1 | C40: Režģogu betonēšana Betons C40/50 ar kristalizējošu piedevu SHOMBURG BETOCRETE-CP-360-WP, betons ar betona piegādi, sūknēšanu, vibrēšanu, līdzināšanu, mitrināšanu, plēves piesegšanu, tehnoloģisko un deformācijas šuvju izveidi, ieliekamo detaļu iebetonēšanu, ja nepieciešams/ Pile cap , Concrete C40/50 whith crystallizing additive SHOMBURG BETOCRETE-CP-360-WP, concrete with concrete delivery, pumping, vibrating, leveling, wetting, covering with film, creating technological and deformation joints, concreting of insert parts, if necessary | D40: m3 | E40: 91.19
A41: =A40+1 -> 22 | B41: R-9.1 | C41: Režģogu betonēšana Betons C40/50 ar kristalizējošu piedevu SHOMBURG BETOCRETE-CP-360-WP, betons ar betona piegādi, sūknēšanu, vibrēšanu, līdzināšanu, mitrināšanu, plēves piesegšanu, tehnoloģisko un deformācijas šuvju izveidi, ieliekamo detaļu iebetonēšanu, ja nepieciešams/ Pile cap , Concrete C40/50 whith crystallizing additive SHOMBURG BETOCRETE-CP-360-WP, concrete with concrete delivery, pumping, vibrating, leveling, wetting, covering with film, creating technological and deformation joints, concreting of insert parts, if necessary | D41: m3 | E41: 25.08
A42: =A41+1 -> 23 | C42: Režģogu stiegrošana un palīgmateriāli (distanceri, sienamās stieples, konusi, uzgriežņi u.c.), stiegrojums B500B / Sheet pile cap beam reinforcement and consumables (spacers, wall wires, cones, bolts etc.), reinforcement B500B | D42: t | E42: 256.75
C44: Pandusa monolītā dzelzsbetona plātne/ Ramp reinforced concrete foundation structures | D44: m2 | E44: 424.27
A45: =A42+1 -> 24 | C45: Veidņu (apjoms precizējams veidņu izklājumā) , tsk. (palīgmateriāli (kokmateriāli, saplāksnis, stiprinājumi, caurlītes, konusi, aizbāžņi, eļļa, plēve) montāža, noma, demontāža režģogiem/ Formwork (volume to be specified in the formwork layout), incl. (auxiliary materials (timber, plywood, fasteners, tubes, cones, plugs, oil, film) assembly, rental, dismantling | D45: kpl | E45: 1
...

Sheet 1-3S
F1: Lokālā tāme Nr./Local estimate No | G1: 1-3
F2: Nesošās sienas un kolonnas/ Load-bearing walls, columns
A4: =KS!C4 -> Būves nosaukums/Building: Daudzīvokļu ēka / Residental building C2-10
A5: =KS!C5 -> Objekta nosaukums/Object: Dzīvojamās ēkas C2-10 jaunbūve/ Residential building C2-10
A6: =KS!C6 -> Objekta adrese/Object adress: Andrejostas iela 35, Rīga, LV-1045 | M6: Tāmes izmaksas | O6: 0
P8: Tāme sastādīta/Date _____. gada ____. ____________
F10: Vienības izmaksas/Unit rate | N10: Kopā uz visu apjomu/Total amount
A11: N.p.k./No | B11: Kods*/Code | C11: Būvdarbu nosaukums/Description of the construction work | D11: Mērvienība/ Unit | E11: Daudzums/ Quantity | F11: laika norma (c/h)/time rate (w/h) | G11: darba samaksas likme* (euro/h)/labour wage rate (euro/h)* | H11: darba alga/ salary | I11: būvizstrādājumi/ materials | J11: mehānismi/ mechanisms | K11: kopā/ total | L11: darbietilpība (c/h)/labor (w/h) | M11: darba alga/ salary | N11: būvizstrādājumi/ materials | O11: mehānismi/ mechanisms | P11: summa/ Total
A12: 1 | B12: 2 | C12: 3 | D12: 4 | E12: 5 | F12: =E12+1 -> 6 | G12: =F12+1 -> 7 | H12: =G12+1 -> 8 | I12: =H12+1 -> 9 | J12: =I12+1 -> 10 | K12: =J12+1 -> 11 | L12: =K12+1 -> 12 | M12: =L12+1 -> 13 | ... P12: =O12+1 -> 16
A14: 1 | C14: Detalizācijas rasējumu izstrāde saliekamajām DzKD / Development of detailed drawings for prefabricated DzKD | D14: kpl | E14: 1
C15: Sienas/Walls
C16: Dūmu šahtu konstrukcijas / Smoke shaft structures
C17: Monolīta dzelzsbetona siena / Reinforced concrete wall, b=160mm
A18: =A14+1 -> 2 | C18: Veidņu (apjoms precizējams veidņu izklājumā) , tsk. (palīgmateriāli (kokmateriāli, saplāksnis, stiprinājumi, caurlītes, konusi, aizbāžņi, eļļa, plēve) montāža, noma, demontāža/ Formwork (volume to be specified in the formwork layout), incl. (auxiliary materials (timber, plywood, fasteners, tubes, cones, plugs, oil, film) assembly, rental, dismantling | D18: m2 | E18: 46.88
A19: =A18+1 -> 3 | C19: Sienu betonēšana Betons C40/50, betons ar betona piegādi, sūknēšanu, vibrēšanu, līdzināšanu, mitrināšanu, plēves piesegšanu, tehnoloģisko un deformācijas šuvju izveidi, ieliekamo detaļu iebetonēšanu, ja nepieciešams/ Reinforced concrete wall, Concrete C40/50, concrete with concrete delivery, pumping, vibrating, leveling, wetting, covering with film, creating technological and deformation joints, concreting of insert parts, if necessary | D19: m3 | E19: 3.75
A20: =A19+1 -> 4 | C20: Sienu stiegrošana un palīgmateriāli (distanceri, sienamās stieples, konusi, uzgriežņi u.c.), stiegrojums B500B / Wall reinforcement and consumables (spacers, wall wires, cones, bolts etc.), reinforcement B500B | D20: t | E20: 0.53
C21: Monolītā dzelzsbetona sienas / Reinforced concrete walls
C22: Monolīta dzelzsbetona siena / Reinforced concrete wall, b=180mm
A23: =A20+1 -> 5 | C23: Veidņu (apjoms precizējams veidņu izklājumā) , tsk. (palīgmateriāli (kokmateriāli, saplāksnis, stiprinājumi, caurlītes, konusi, aizbāžņi, eļļa, plēve) montāža, noma, demontāža/ Formwork (volume to be specified in the formwork layout), incl. (auxiliary materials (timber, plywood, fasteners, tubes, cones, plugs, oil, film) assembly, rental, dismantling | D23: m2 | E23: 9.11
A24: =A23+1 -> 6 | C24: Sienu betonēšana Betons C40/50 , betons ar betona piegādi, sūknēšanu, vibrēšanu, līdzināšanu, mitrināšanu, plēves piesegšanu, tehnoloģisko un deformācijas šuvju izveidi, ieliekamo detaļu iebetonēšanu, ja nepieciešams/ Reinforced concrete wall, Concrete C40/50, concrete with concrete delivery, pumping, vibrating, leveling, wetting, covering with film, creating technological and deformation joints, concreting of insert parts, if necessary | D24: m3 | E24: 0.82
A25: =A24+1 -> 7 | C25: Sienu stiegrošana un palīgmateriāli (distanceri, sienamās stieples, konusi, uzgriežņi u.c.), stiegrojums B500B / Wall reinforcement and consumables (spacers, wall wires, cones, bolts etc.), reinforcement B500B | D25: t | E25: 0.12
C26: Monolīta dzelzsbetona siena / Reinforced concrete wall, b=200mm
A27: =A25+1 -> 8 | C27: Veidņu (apjoms precizējams veidņu izklājumā) , tsk. (palīgmateriāli (kokmateriāli, saplāksnis, stiprinājumi, caurlītes, konusi, aizbāžņi, eļļa, plēve) montāža, noma, demontāža/ Formwork (volume to be specified in the formwork layout), incl. (auxiliary materials (timber, plywood, fasteners, tubes, cones, plugs, oil, film) assembly, rental, dismantling | D27: m2 | E27: 731.9
A28: =A27+1 -> 9 | C28: Sienu betonēšana Betons C40/50 , betons ar betona piegādi, sūknēšanu, vibrēšanu, līdzināšanu, mitrināšanu, plēves piesegšanu, tehnoloģisko un deformācijas šuvju izveidi, ieliekamo detaļu iebetonēšanu, ja nepieciešams/ Reinforced concrete wall, Concrete C40/50, concrete with concrete delivery, pumping, vibrating, leveling, wetting, covering with film, creating technological and deformation joints, concreting of insert parts, if necessary | D28: m3 | E28: 73.19
A29: =A28+1 -> 10 | C29: Sienu stiegrošana un palīgmateriāli (distanceri, sienamās stieples, konusi, uzgriežņi u.c.), stiegrojums B500B / Wall reinforcement and consumables (spacers, wall wires, cones, bolts etc.), reinforcement B500B | D29: t | E29: 10.32
C30: Monolīta dzelzsbetona siena / Reinforced concrete wall, b=220mm
A31: =A29+1 -> 11 | C31: Veidņu (apjoms precizējams veidņu izklājumā) , tsk. (palīgmateriāli (kokmateriāli, saplāksnis, stiprinājumi, caurlītes, konusi, aizbāžņi, eļļa, plēve) montāža, noma, demontāža/ Formwork (volume to be specified in the formwork layout), incl. (auxiliary materials (timber, plywood, fasteners, tubes, cones, plugs, oil, film) assembly, rental, dismantling | D31: m2 | E31: 369.09
A32: =A31+1 -> 12 | C32: Sienu betonēšana Betons C40/50 , betons ar betona piegādi, sūknēšanu, vibrēšanu, līdzināšanu, mitrināšanu, plēves piesegšanu, tehnoloģisko un deformācijas šuvju izveidi, ieliekamo detaļu iebetonēšanu, ja nepieciešams/ Reinforced concrete wall, Concrete C40/50, concrete with concrete delivery, pumping, vibrating, leveling, wetting, covering with film, creating technological and deformation joints, concreting of insert parts, if necessary | D32: m3 | E32: 40.6
